Assim como em várias outras linguagens orientadas a objeto, C++ possui os blocos
try-catch. O bloco try envolve código que pode vir a lançar uma exceção, throw é
o responsável por lançar a exceção, e catch é o handler responsável por tratar a
exceção lançada. Desse modo, o controle do programa é passado para o catch que 
captura a exceção. Em C++, um throw aceita apenas um parâmetro, que é passado 
como argumento para o cath responsável. O tipo do parâmetro de um catch é 
importante, uma vez que o parâmetro lançado pelo throw é comparado ao parâmetro 
que o cath recebe. Mesmo que haja mais de um catch com parâmetro igual, por ex, 
vários catches que aceitam um parâmetro do tipo int, apenas o primeiro trata a 
exceção. Ainda pode haver um catch padrão indicado por catch(...), que captua 
qualquer exceção. A execurção do programa continua após todo o bloco try-catch, 
e não depois do throw [1].
A biblioteca padrã do C++ possui uma classe específica para declarar objetos que 
possam lançar exceções: exception. Essa classe tem um membro virtual chamado de
what, que retorna uma sequência de caracteres, podendo ser sobrescrito em
classes que herdam de exception. Há exceções já definidas nesta biblioteca [1].
A implementação depende de compilador, e uma escolha possível é manter o código 
do bloco try tão rápido quanto qualquer outro código. No entanto, nesta
abordagem, a propagação e captura da exceção depende da profundidade do stack, 
pois, diferente de Java, onde que a exceção deve ser tratada pela função 
chamadora do método que gerou a exceção, em C++ não é obrigatório capturar a 
exceção [2], e ela é propagada pelo stack [3].
Quando uma exceção é lançada, um objeto do tipo exception é criado a partir do
objeto que lançou a exceção. A partir disso, o compilador busca um catch em um 
contexto acima no stack que possa lidar com a exceção. Se nenhum catch for
encontrado, o sistema chama a função predefinida de run-time terminate. Se um
catch for encontrado, seu parâmetro é inicializado e começa o processo de 
subir no stack, que envolve chamar o destrutor de todos os objetos que foram
criados e não foram destruídos entre o começo do bloco try que é associado ao
catch em questão. Não é possível dar o controle do programa a um catch a partir
de um goto, por exemplo, apenas com uma exceção sendo lançada [4].
[1] http://www.cplusplus.com/doc/tutorial/exceptions/
[2] https://hackernoon.com/error-handling-in-c-or-why-you-should-use-eithers-in-favor-of-exceptions-and-error-codes-f0640912eb45
[3] https://www.cprogramming.com/tutorial/exceptions.html
[4] https://msdn.microsoft.com/en-us/library/hh254939.aspx 
